Workbook

Sheet Tasks
A1: Track | B1: Owner | C1: Phase | D1: Task # | E1: Task | F1: Status | G1: Dependencies / Notes
A2: C - Data/Content/Platform | B2: Alan | C2: 0. Setup | D2: 1 | E2: Create repo structure (/frontend, /backend, /docs) | F2: Done | G2: All three agree on structure Week 1
A3: C - Data/Content/Platform | B3: Alan | C3: 0. Setup | D3: 2 | E3: Provision Supabase project (Postgres + Storage) | F3: Done
A4: C - Data/Content/Platform | B4: Alan | C4: 0. Setup | D4: 3 | E4: Get MyScript iink API keys | F4: Done
A5: C - Data/Content/Platform | B5: Alan | C5: 0. Setup | D5: 4 | E5: Set up hosting accounts (Vercel, Railway/Render) | F5: Done
A6: C - Data/Content/Platform | B6: All | C6: C - Data/Content/Platform | D6: 5 | E6: C - Data/Content/Platform | F6: In Progress | G6: I suggest to just use private api call for access
A8: C - Data/Content/Platform | B8: All | C8: 1. Data Layer | D8: 7 | E8: Write SQL migrations / table definitions | F8: Not Started | G8: Depends on #6
A9: C - Data/Content/Platform | B9: Richard | C9: 1. Data Layer | D9: 8 | E9: Seed problems table (~20-30 problems), sourced via school contacts | F9: Not Started | G9: Leverage school relationship for real curriculum content
A10: C - Data/Content/Platform | B10: Jeff | C10: 1. Data Layer | D10: 9 | E10: Seed misconception_rules and hints with first batch | F10: Not Started | G10: Coordinate wording/format with Dev B
A11: C - Data/Content/Platform | B11: All | C11: 1. Data Layer | D11: 10 | E11: Enable Supabase Row Level Security policies | F11: Not Started
A12: C - Data/Content/Platform | B12: All (led by C) | C12: Sync | D12: 11 | E12: Week 1: agree API contract / Pydantic schema across all 3 tracks | F12: In Progress | G12: Hard sync point - do before splitting off, see doc at math-tutor-mvp/docs/api_contract_draft_20260728.md
A13: C - Data/Content/Platform | B13: All | C13: 11. Security | D13: 47 | E13: Enforce HTTPS everywhere | F13: Not Started
A14: C - Data/Content/Platform | B14: Alan | C14: 11. Security | D14: 48 | E14: Keep MyScript/Supabase keys server-side only | F14: Done
A15: C - Data/Content/Platform | B15: Alan | C15: 11. Security | D15: 49 | E15: Store LaTeX only, not raw ink strokes, by default | F15: Not Started
A16: C - Data/Content/Platform | B16: Alan | C16: 11. Security | D16: 50 | E16: Add simple student access code | F16: Not Started | G16: Tied to UI
A17: C - Data/Content/Platform | B17: All | C17: 11. Security | D17: 51 | E17: Tighten Supabase RLS policies once access code exists | F17: Not Started | G17: Depends on #50
A18: C - Data/Content/Platform | B18: All | C18: 12. Testing/QA | D18: 54 | E18: Organize manual QA with real kids' handwriting via school | F18: Not Started | G18: Dev A + B support
A19: C - Data/Content/Platform | B19: Richard | C19: 12. Testing/QA | D19: 55 | E19: Verify curriculum coverage vs SLO tussendoelen groep 7/8 | F19: Not Started
A20: C - Data/Content/Platform | B20: All | C20: 13. Deployment | D20: 56 | E20: Deploy backend to Railway/Render, connect Supabase | F20: Not Started | G20: Depends on B's backend
A21: C - Data/Content/Platform | B21: Alan | C21: 13. Deployment | D21: 57 | E21: Deploy frontend to Vercel, point at backend API URL | F21: Not Started | G21: Depends on A's frontend
A22: C - Data/Content/Platform | B22: All | C22: 13. Deployment | D22: 58 | E22: Smoke-test production environment end-to-end | F22: Not Started
A23: C - Data/Content/Platform | B23: Dev C (Leader) | C23: 13. Deployment | D23: 59 | E23: Set up monitoring / error logging (e.g. Sentry) | F23: Not Started
A24: C - Data/Content/Platform | B24: Richard | C24: 14. Content | D24: 60 | E24: Expand problem bank across all rekenen domains | F24: Blocked | G24: Post-MVP not relavant for now
A25: C - Data/Content/Platform | B25: Jeff | C25: 14. Content | D25: 61 | E25: Expand misconception rule library from real usage data | F25: Blocked | G25: Post-MVP not relavant for now
A26: C - Data/Content/Platform | B26: Jeff | C26: 14. Content | D26: 62 | E26: Iterate hint wording based on observed confusion | F26: Blocked | G26: Post-MVP not relavant for now
A28: C - Data/Content/Platform | B28: All | C28: 1. Data Layer | D28: 6 | E28: Design Supabase schema: problems, attempts, attempt_steps, misconception_rules, hints | F28: Not Started | G28: Blocks B's DB client work
A29: B - Backend/Math Engine | B29: All | C29: 2. Backend Skeleton | D29: 12 | E29: Scaffold FastAPI project with Pydantic models | F29: Not Started | G29: Depends on #11 API contract
A30: B - Backend/Math Engine | B30: All | C30: 2. Backend Skeleton | D30: 13 | E30: Set up Supabase Python client / DB connection layer | F30: Not Started | G30: Depends on #6/#7
A31: B - Backend/Math Engine | B31: Richard | C31: 2. Backend Skeleton | D31: 14 | E31: Implement GET /problems/{id} | F31: Not Started
A32: B - Backend/Math Engine | B32: Richard | C32: 2. Backend Skeleton | D32: 15 | E32: Implement POST /attempts (persist attempt + steps) | F32: Not Started
A33: B - Backend/Math Engine | B33: All | C33: 2. Backend Skeleton | D33: 16 | E33: Add error handling, validation, logging | F33: Not Started
A34: B - Backend/Math Engine | B34: Alan | C34: 3. Recognition | D34: 18 | E34: Build Recognition Service wrapper around MyScript API | F34: Not Started | G34: Depends on #3 API keys
A35: B - Backend/Math Engine | B35: Alan | C35: 3. Recognition | D35: 19 | E35: Implement POST /recognize endpoint | F35: Not Started
A36: B - Backend/Math Engine | B36: Alan | C36: 3. Recognition | D36: 21 | E36: Handle low-confidence recognition (flag for confirmation) | F36: Not Started
A37: B - Backend/Math Engine | B37: Alan | C37: 4. Math Parser | D37: 22 | E37: Implement LaTeX to SymPy expression parsing | F37: Not Started
A38: B - Backend/Math Engine | B38: Alan | C38: 4. Math Parser | D38: 23 | E38: Build canonical-form normalizer | F38: Not Started
A39: B - Backend/Math Engine | B39: Alan | C39: 4. Math Parser | D39: 24 | E39: Unit test parser: fractions, mixed numbers, decimals, negatives | F39: Not Started
A41: B - Backend/Math Engine | B41: Jeff | C41: 5. Step Evaluator | D41: 25 | E41: Implement expression validity check | F41: Not Started
A42: B - Backend/Math Engine | B42: Jeff | C42: 5. Step Evaluator | D42: 26 | E42: Implement internal math correctness check | F42: Not Started
A43: B - Backend/Math Engine | B43: Jeff | C43: 5. Step Evaluator | D43: 27 | E43: Implement transition validity check (legal derivation) | F43: Not Started
...

Sheet Dashboard
A1: Owner | B1: Total Tasks | C1: Not Started | D1: In Progress | E1: Blocked | F1: Done
A2: Dev A | B2: =COUNTIF(Tasks!$B$2:$B$69,A2) -> 0 | C2: =COUNTIFS(Tasks!$B$2:$B$69,A2,Tasks!$F$2:$F$69,"Not Started") -> 0 | D2: =COUNTIFS(Tasks!$B$2:$B$69,A2,Tasks!$F$2:$F$69,"In Progress") -> 0 | E2: =COUNTIFS(Tasks!$B$2:$B$69,A2,Tasks!$F$2:$F$69,"Blocked") -> 0 | F2: =COUNTIFS(Tasks!$B$2:$B$69,A2,Tasks!$F$2:$F$69,"Done") -> 0
A3: Dev B | B3: =COUNTIF(Tasks!$B$2:$B$69,A3) -> 5 | C3: =COUNTIFS(Tasks!$B$2:$B$69,A3,Tasks!$F$2:$F$69,"Not Started") -> 5 | D3: =COUNTIFS(Tasks!$B$2:$B$69,A3,Tasks!$F$2:$F$69,"In Progress") -> 0 | E3: =COUNTIFS(Tasks!$B$2:$B$69,A3,Tasks!$F$2:$F$69,"Blocked") -> 0 | F3: =COUNTIFS(Tasks!$B$2:$B$69,A3,Tasks!$F$2:$F$69,"Done") -> 0
A4: Dev C (Leader) | B4: =COUNTIF(Tasks!$B$2:$B$69,A4) -> 1 | C4: =COUNTIFS(Tasks!$B$2:$B$69,A4,Tasks!$F$2:$F$69,"Not Started") -> 1 | D4: =COUNTIFS(Tasks!$B$2:$B$69,A4,Tasks!$F$2:$F$69,"In Progress") -> 0 | E4: =COUNTIFS(Tasks!$B$2:$B$69,A4,Tasks!$F$2:$F$69,"Blocked") -> 0 | F4: =COUNTIFS(Tasks!$B$2:$B$69,A4,Tasks!$F$2:$F$69,"Done") -> 0
A5: Dev B + C | B5: =COUNTIF(Tasks!$B$2:$B$69,A5) -> 0 | C5: =COUNTIFS(Tasks!$B$2:$B$69,A5,Tasks!$F$2:$F$69,"Not Started") -> 0 | D5: =COUNTIFS(Tasks!$B$2:$B$69,A5,Tasks!$F$2:$F$69,"In Progress") -> 0 | E5: =COUNTIFS(Tasks!$B$2:$B$69,A5,Tasks!$F$2:$F$69,"Blocked") -> 0 | F5: =COUNTIFS(Tasks!$B$2:$B$69,A5,Tasks!$F$2:$F$69,"Done") -> 0
A6: All (led by C) | B6: =COUNTIF(Tasks!$B$2:$B$69,A6) -> 1 | C6: =COUNTIFS(Tasks!$B$2:$B$69,A6,Tasks!$F$2:$F$69,"Not Started") -> 0 | D6: =COUNTIFS(Tasks!$B$2:$B$69,A6,Tasks!$F$2:$F$69,"In Progress") -> 1 | E6: =COUNTIFS(Tasks!$B$2:$B$69,A6,Tasks!$F$2:$F$69,"Blocked") -> 0 | F6: =COUNTIFS(Tasks!$B$2:$B$69,A6,Tasks!$F$2:$F$69,"Done") -> 0
A7: All | B7: =COUNTIF(Tasks!$B$2:$B$69,A7) -> 12 | C7: =COUNTIFS(Tasks!$B$2:$B$69,A7,Tasks!$F$2:$F$69,"Not Started") -> 11 | D7: =COUNTIFS(Tasks!$B$2:$B$69,A7,Tasks!$F$2:$F$69,"In Progress") -> 1 | E7: =COUNTIFS(Tasks!$B$2:$B$69,A7,Tasks!$F$2:$F$69,"Blocked") -> 0 | F7: =COUNTIFS(Tasks!$B$2:$B$69,A7,Tasks!$F$2:$F$69,"Done") -> 0
A8: TOTAL | B8: =SUM(B2:B7) -> 19 | C8: =SUM(C2:C7) -> 17 | D8: =SUM(D2:D7) -> 2 | E8: =SUM(E2:E7) -> 0 | F8: =SUM(F2:F7) -> 0
